<?xml version="1.0"?>
<robot name="firebot" xmlns:xacro="http://ros.org/wiki/xacro">
    <xacro:include filename="inertial_macros.xacro"/>
    <material name="orange">
        <color rgba="1 0.64 0 1" />
    </material>

    <material name="white">
        <color rgba="1 1 1 1" />
    </material>

    <link name="base_link">

    </link>

    <joint name="chassis_joint" type="fixed">
        <parent link="base_link"/>
        <child link="chassis"/>
        <origin xyz = "-0.35 0 0"/>
    </joint>
    <link name="chassis">
        <visual>
            <geometry>
                <box size= "0.4 0.4 0.57"/>
                <material name="orange"/>
            </geometry>
            <origin xyz="0.2 0 0.280"/>
        </visual>
        <collision>
            <geometry>
                <box size= "0.4 0.4 0.57"/>
            </geometry>
            <origin xyz="0.2 0 0.280"/>
        </collision>
        <xacro:inertial_box mass="0.5" x="0.4" y="0.4" z="0.57">
            <origin xyz="0.2 0 0.280" rpy="0 0 0"/>
        </xacro:inertial_box>
    </link>
    

    <joint name="front_left_wheel_joint" type="continuous">
        <parent link="base_link"/>
        <child link="front_left_wheel"/>
        <origin xyz="0 0.25 0" rpy="-${pi/2} 0 0" />
        <axis xyz="0 0 1" />
    </joint>
    <link name="front_left_wheel">
        <visual>
            <geometry>
                <cylinder radius="0.10115" length="0.05" /> 
            </geometry>
            <material name="white"/>
        </visual>
        <collision>
            <geometry>
                <cylinder radius="0.10115" length="0.05" /> 
            </geometry>
        </collision>
        <xacro:inertial_cylinder mass="0.1" radius="0.10115" length="0.05" >
            <origin xyz="0 0 0" rpy="0 0 0" />
        </xacro:inertial_cylinder>
    </link>


    <joint name="front_right_wheel_joint" type="continuous">
        <parent link="base_link"/>
        <child link="front_right_wheel"/>
        <origin xyz="0 -0.25 0" rpy="${pi/2} 0 0" />
        <axis xyz="0 0 -1" />
    </joint>
    <link name="front_right_wheel">
        <visual>
            <geometry>
                <cylinder radius="0.10115" length="0.05" /> 
            </geometry>
            <material name="white"/>
        </visual>
        <collision>
            <geometry>
                <cylinder radius="0.10115" length="0.05" /> 
            </geometry>
        </collision>
        <xacro:inertial_cylinder mass="0.1" radius="0.10115" length="0.05" >
            <origin xyz="0 0 0" rpy="0 0 0" />
        </xacro:inertial_cylinder>
    </link>

    <joint name="back_left_wheel_joint" type="fixed">
        <parent link="base_link"/>
        <child link="back_left_wheel"/>
        <origin xyz="-0.30 0.25 0" rpy="-${pi/2} 0 0" />
    </joint>
    <link name="back_left_wheel">
        <visual>
            <geometry>
                <cylinder radius="0.10115" length="0.05" /> 
            </geometry>
            <material name="white"/>
        </visual>
        <collision>
            <geometry>
                <cylinder radius="0.10115" length="0.05" /> 
            </geometry>
        </collision>
        <xacro:inertial_cylinder mass="0.1" radius="0.10115" length="0.05" >
            <origin xyz="0 0 0" rpy="0 0 0" />
        </xacro:inertial_cylinder>
    </link>


    <joint name="back_right_wheel_joint" type="fixed">
        <parent link="base_link"/>
        <child link="back_right_wheel"/>
        <origin xyz="-0.30 -0.25 0" rpy="${pi/2} 0 0" />
    </joint>
    <link name="back_right_wheel">
        <visual>
            <geometry>
                <cylinder radius="0.10115" length="0.05" /> 
            </geometry>
            <material name="white"/>
        </visual>
        <collision>
            <geometry>
                <cylinder radius="0.10115" length="0.05" /> 
            </geometry>
        </collision>
        <xacro:inertial_cylinder mass="0.1" radius="0.10115" length="0.05" >
            <origin xyz="0 0 0" rpy="0 0 0" />
        </xacro:inertial_cylinder>
    </link>
     <gazebo reference="back_left_wheel">
        <mu1 value="0.001"/>
        <mu2 value="0.001"/>
    </gazebo>
    <gazebo reference="back_right_wheel">
        <mu1 value="0.001"/>
        <mu2 value="0.001"/>
    </gazebo>
</robot>
